Workbook

Sheet Leyenda
A1: Cómo usar esta calculadora
A3: Colores
A4: Azul | B4: Entrada editable.
A5: Amarillo | B5: Entrada CRÍTICA (TRM, costos de proveedor, margen).
A6: Negro | B6: Fórmula — no tocar.
A7: Verde | B7: Trae un valor de 'Supuestos'.
A9: Idea central
A10: Las tablas NO llevan fijos | B10: Solo el COSTO DE ENVÍO (variable). Así 'Margen' = ingreso − costo de envío (margen de contribución) y no confunde.
A11: ¿Gano por envío? | B11: Mirá 'Precio − Costo de envío'. Si es positivo, cada envío deja plata.
A12: Fijos | B12: Van aparte en 'Resumen'. Son bajos (~15.000/mes) → se cubren con poquísimo volumen.
A14: Hojas
A15: Supuestos | B15: Costos AWS/Meta, TRM, margen, fijos, parámetros.
A16: EM/EAU/EAP/SMS/WhatsApp/Voz | B16: Costo de envío, precio y margen por volumen.
A17: Cotizador | B17: Cotización rápida por canal.
A18: Adjunto URL vs archivo | B18: Compara mandar el documento adjunto vs como enlace (S3).
A19: Resumen | B19: Fijos + punto de equilibrio por canal.
A21: A calibrar
A22: SMS | B22: AWS no publica precio plano (varía por operador). El valor es referencia Twilio; confirmá con tu REPORTE DE USO de AWS o un proveedor LOCAL (mucho más barato).
A23: WhatsApp | B23: Es de META: marketing CO ~US$0.0125 (~51 COP).
A24: Voz | B24: ~US$0.0301/min saliente CO; el número va en 'fijos'.
A25: Email (SES) | B25: US$0.10/1.000 correos y US$0.12/GB de adjunto.

Sheet Supuestos
A1: MailConnect — Supuestos de la calculadora de precios
A2: Editá SOLO las celdas azules; las amarillas son las críticas. Fuentes en la columna D. Región AWS: us-east-1.
A4: TASA DE CAMBIO
A5: TRM (COP por USD) | B5: 3532 | C5: COP/USD | D5: TRM del día (AWS/Meta facturan en USD)
A6: Colchón de devaluación | B6: 0.08 | C6: % | D6: margen extra por si sube el dólar
A7: TRM efectiva | B7: =B5*(1+B6) | C7: COP/USD | D7: la que usa todo el modelo
A9: COSTOS AWS (USD)
A10: SES — envío de 1 correo | B10: 0.0001 | C10: USD/correo | D10: AWS SES: US$0.10 por 1.000 correos
A11: SES — datos de adjunto | B11: 0.000117 | C11: USD/MB | D11: AWS SES: US$0.12/GB ÷ 1024
A12: SNS — 1 publicación | B12: 5e-07 | C12: USD/msg | D12: ~US$0.50 por 1M
A13: Lambda — 1 solicitud | B13: 2e-07 | C13: USD/req | D13: US$0.20 por 1M
A14: Lambda — GB-segundo | B14: 1.667e-05 | C14: USD/GB-s | D14: memoria x duración
A15: DynamoDB — 1 escritura | B15: 1.25e-06 | C15: USD/write | D15: US$1.25 por 1M (on-demand)
A16: S3 — almacenamiento | B16: 0.023 | C16: USD/GB-mes | D16: guardar archivos
A17: S3 — egreso (descargas) | B17: 0.09 | C17: USD/GB | D17: US$0.09/GB de salida a internet (para adjunto por URL)
A18: SQS — 1 solicitud | B18: 4e-07 | C18: USD/req | D18: US$0.40 por 1M
A19: CloudWatch Logs — 1 GB | B19: 0.5 | C19: USD/GB | D19: ingesta de logs
A21: COSTOS DE PROVEEDOR (USD) — ¡calibrar con tu factura!
A22: SMS — 1 segmento a Colombia | B22: 0.0525 | C22: USD/segmento | D22: AWS NO publica precio plano (varía por operador; ver reporte de uso). Ref. Twilio CO US$0.0525; local/AWS suele ser MENOR — CONFIRMAR
A23: WhatsApp — plantilla marketing a Colombia | B23: 0.0125 | C23: USD/msg | D23: META (no AWS): marketing CO ~US$0.0125 (~51 COP), por-mensaje desde jul-2025
A24: Voz — 1 minuto saliente a Colombia | B24: 0.0301 | C24: USD/min | D24: ~US$0.0301/min saliente CO (Amazon Connect/EUM); número aparte
A26: PARÁMETROS DEL PIPELINE
A27: Estados SNS por correo | B27: 3 | C27: eventos | D27: el código escribe hasta 5
A28: Tamaño de parte (troceo) | B28: 250 | C28: reg/parte | D28: REGISTERS_FOR_EM
A29: Escrituras DynamoDB por correo | B29: 5 | C29: writes | D29: sendStatus+sendDetail+estados
A30: Escrituras DynamoDB por SMS/WSP/Voz | B30: 3 | C30: writes | D30: sendStatus+messageIndex+estado
A31: Segundos de Lambda por mensaje | B31: 0.05 | C31: s/msg | D31: prepare+send amortizado
A32: Memoria Lambda | B32: 0.5 | C32: GB | D32: costo por GB-segundo
A33: GB de logs por 1.000 mensajes | B33: 0.002 | C33: GB/1000 | D33: prints del pipeline
A34: MB de adjunto — EAU | B34: 1 | C34: MB | D34: adjunto único
A35: MB de adjunto — EAP | B35: 2 | C35: MB | D35: adjunto personalizado
A36: Segmentos por SMS (base) | B36: 1 | C36: segmentos | D36: para las tablas
A37: % que descarga el adjunto (URL) | B37: 0.3 | C37: % | D37: cuántos hacen clic en el enlace (para 'Adjunto URL vs archivo')
A39: NEGOCIO
A40: Margen bruto objetivo | B40: 0.8 | C40: % | D40: piso para el precio sugerido
A41: IVA | B41: 0.19 | C41: % | D41: Colombia
A42: Comisión Wompi (%) | B42: 0.0265 | C42: % | D42: sobre la recarga
A43: Comisión Wompi (fija) | B43: 700 | C43: COP/tx | D43: por transacción
A44: Mínimo por campaña | B44: 5000 | C44: COP | D44: cobro mínimo
A46: COSTOS FIJOS MENSUALES (COP) — NO se reparten en las tablas de canal (ver hoja Resumen)
...

Sheet EM
A1: EM — Email marketing — sin adjunto
A2: Solo COSTO DE ENVÍO (variable), SIN costos fijos (ver hoja 'Resumen'). Margen = Ingreso − costo de envío = margen de contribución. Si 'Precio lista' ≥ 'Precio mín.', llegás al margen objetivo. 'Precio lista' (azul) es editable por tramo.
A4: Volumen mensual (correos) | B4: Costo de envío unit. (COP) | C4: Precio mín. ≥margen (COP) | D4: Precio lista (COP) | E4: Ingreso (COP) | F4: Margen (COP) | G4: % Margen | H4: Total + IVA (COP)
A5: 1000 | B5: =Supuestos!$B$63 | C5: =B5/(1-Supuestos!$B$40) | D5: 30 | E5: =A5*D5 | F5: =E5-A5*B5 | G5: =IF(D5=0,0,(D5-B5)/D5) | H5: =E5*(1+Supuestos!$B$41)
A6: 2000 | B6: =Supuestos!$B$63 | C6: =B6/(1-Supuestos!$B$40) | D6: 28 | E6: =A6*D6 | F6: =E6-A6*B6 | G6: =IF(D6=0,0,(D6-B6)/D6) | H6: =E6*(1+Supuestos!$B$41)
A7: 5000 | B7: =Supuestos!$B$63 | C7: =B7/(1-Supuestos!$B$40) | D7: 27 | E7: =A7*D7 | F7: =E7-A7*B7 | G7: =IF(D7=0,0,(D7-B7)/D7) | H7: =E7*(1+Supuestos!$B$41)
A8: 10000 | B8: =Supuestos!$B$63 | C8: =B8/(1-Supuestos!$B$40) | D8: 25 | E8: =A8*D8 | F8: =E8-A8*B8 | G8: =IF(D8=0,0,(D8-B8)/D8) | H8: =E8*(1+Supuestos!$B$41)
A9: 20000 | B9: =Supuestos!$B$63 | C9: =B9/(1-Supuestos!$B$40) | D9: 21 | E9: =A9*D9 | F9: =E9-A9*B9 | G9: =IF(D9=0,0,(D9-B9)/D9) | H9: =E9*(1+Supuestos!$B$41)
A10: 50000 | B10: =Supuestos!$B$63 | C10: =B10/(1-Supuestos!$B$40) | D10: 19 | E10: =A10*D10 | F10: =E10-A10*B10 | G10: =IF(D10=0,0,(D10-B10)/D10) | H10: =E10*(1+Supuestos!$B$41)
A11: 100000 | B11: =Supuestos!$B$63 | C11: =B11/(1-Supuestos!$B$40) | D11: 14 | E11: =A11*D11 | F11: =E11-A11*B11 | G11: =IF(D11=0,0,(D11-B11)/D11) | H11: =E11*(1+Supuestos!$B$41)
A12: 200000 | B12: =Supuestos!$B$63 | C12: =B12/(1-Supuestos!$B$40) | D12: 9 | E12: =A12*D12 | F12: =E12-A12*B12 | G12: =IF(D12=0,0,(D12-B12)/D12) | H12: =E12*(1+Supuestos!$B$41)
A13: 500000 | B13: =Supuestos!$B$63 | C13: =B13/(1-Supuestos!$B$40) | D13: 5 | E13: =A13*D13 | F13: =E13-A13*B13 | G13: =IF(D13=0,0,(D13-B13)/D13) | H13: =E13*(1+Supuestos!$B$41)
A14: 1000000 | B14: =Supuestos!$B$63 | C14: =B14/(1-Supuestos!$B$40) | D14: 4 | E14: =A14*D14 | F14: =E14-A14*B14 | G14: =IF(D14=0,0,(D14-B14)/D14) | H14: =E14*(1+Supuestos!$B$41)

Sheet EAU
A1: EAU — Email con adjunto único
A2: Solo COSTO DE ENVÍO (variable), SIN costos fijos (ver hoja 'Resumen'). Margen = Ingreso − costo de envío = margen de contribución. Si 'Precio lista' ≥ 'Precio mín.', llegás al margen objetivo. 'Precio lista' (azul) es editable por tramo.
A4: Volumen mensual (correos) | B4: Costo de envío unit. (COP) | C4: Precio mín. ≥margen (COP) | D4: Precio lista (COP) | E4: Ingreso (COP) | F4: Margen (COP) | G4: % Margen | H4: Total + IVA (COP)
A5: 1000 | B5: =Supuestos!$B$64 | C5: =B5/(1-Supuestos!$B$40) | D5: 45 | E5: =A5*D5 | F5: =E5-A5*B5 | G5: =IF(D5=0,0,(D5-B5)/D5) | H5: =E5*(1+Supuestos!$B$41)
A6: 2000 | B6: =Supuestos!$B$64 | C6: =B6/(1-Supuestos!$B$40) | D6: 42 | E6: =A6*D6 | F6: =E6-A6*B6 | G6: =IF(D6=0,0,(D6-B6)/D6) | H6: =E6*(1+Supuestos!$B$41)
A7: 5000 | B7: =Supuestos!$B$64 | C7: =B7/(1-Supuestos!$B$40) | D7: 40 | E7: =A7*D7 | F7: =E7-A7*B7 | G7: =IF(D7=0,0,(D7-B7)/D7) | H7: =E7*(1+Supuestos!$B$41)
A8: 10000 | B8: =Supuestos!$B$64 | C8: =B8/(1-Supuestos!$B$40) | D8: 37 | E8: =A8*D8 | F8: =E8-A8*B8 | G8: =IF(D8=0,0,(D8-B8)/D8) | H8: =E8*(1+Supuestos!$B$41)
A9: 20000 | B9: =Supuestos!$B$64 | C9: =B9/(1-Supuestos!$B$40) | D9: 31 | E9: =A9*D9 | F9: =E9-A9*B9 | G9: =IF(D9=0,0,(D9-B9)/D9) | H9: =E9*(1+Supuestos!$B$41)
A10: 50000 | B10: =Supuestos!$B$64 | C10: =B10/(1-Supuestos!$B$40) | D10: 28 | E10: =A10*D10 | F10: =E10-A10*B10 | G10: =IF(D10=0,0,(D10-B10)/D10) | H10: =E10*(1+Supuestos!$B$41)
A11: 100000 | B11: =Supuestos!$B$64 | C11: =B11/(1-Supuestos!$B$40) | D11: 21 | E11: =A11*D11 | F11: =E11-A11*B11 | G11: =IF(D11=0,0,(D11-B11)/D11) | H11: =E11*(1+Supuestos!$B$41)
A12: 200000 | B12: =Supuestos!$B$64 | C12: =B12/(1-Supuestos!$B$40) | D12: 14 | E12: =A12*D12 | F12: =E12-A12*B12 | G12: =IF(D12=0,0,(D12-B12)/D12) | H12: =E12*(1+Supuestos!$B$41)
A13: 500000 | B13: =Supuestos!$B$64 | C13: =B13/(1-Supuestos!$B$40) | D13: 8 | E13: =A13*D13 | F13: =E13-A13*B13 | G13: =IF(D13=0,0,(D13-B13)/D13) | H13: =E13*(1+Supuestos!$B$41)
A14: 1000000 | B14: =Supuestos!$B$64 | C14: =B14/(1-Supuestos!$B$40) | D14: 6 | E14: =A14*D14 | F14: =E14-A14*B14 | G14: =IF(D14=0,0,(D14-B14)/D14) | H14: =E14*(1+Supuestos!$B$41)

Sheet EAP
A1: EAP — Email con adjunto personalizado
A2: Solo COSTO DE ENVÍO (variable), SIN costos fijos (ver hoja 'Resumen'). Margen = Ingreso − costo de envío = margen de contribución. Si 'Precio lista' ≥ 'Precio mín.', llegás al margen objetivo. 'Precio lista' (azul) es editable por tramo.
A4: Volumen mensual (correos) | B4: Costo de envío unit. (COP) | C4: Precio mín. ≥margen (COP) | D4: Precio lista (COP) | E4: Ingreso (COP) | F4: Margen (COP) | G4: % Margen | H4: Total + IVA (COP)
A5: 1000 | B5: =Supuestos!$B$65 | C5: =B5/(1-Supuestos!$B$40) | D5: 60 | E5: =A5*D5 | F5: =E5-A5*B5 | G5: =IF(D5=0,0,(D5-B5)/D5) | H5: =E5*(1+Supuestos!$B$41)
A6: 2000 | B6: =Supuestos!$B$65 | C6: =B6/(1-Supuestos!$B$40) | D6: 55 | E6: =A6*D6 | F6: =E6-A6*B6 | G6: =IF(D6=0,0,(D6-B6)/D6) | H6: =E6*(1+Supuestos!$B$41)
A7: 5000 | B7: =Supuestos!$B$65 | C7: =B7/(1-Supuestos!$B$40) | D7: 50 | E7: =A7*D7 | F7: =E7-A7*B7 | G7: =IF(D7=0,0,(D7-B7)/D7) | H7: =E7*(1+Supuestos!$B$41)
A8: 10000 | B8: =Supuestos!$B$65 | C8: =B8/(1-Supuestos!$B$40) | D8: 46 | E8: =A8*D8 | F8: =E8-A8*B8 | G8: =IF(D8=0,0,(D8-B8)/D8) | H8: =E8*(1+Supuestos!$B$41)
A9: 20000 | B9: =Supuestos!$B$65 | C9: =B9/(1-Supuestos!$B$40) | D9: 38 | E9: =A9*D9 | F9: =E9-A9*B9 | G9: =IF(D9=0,0,(D9-B9)/D9) | H9: =E9*(1+Supuestos!$B$41)
A10: 50000 | B10: =Supuestos!$B$65 | C10: =B10/(1-Supuestos!$B$40) | D10: 33 | E10: =A10*D10 | F10: =E10-A10*B10 | G10: =IF(D10=0,0,(D10-B10)/D10) | H10: =E10*(1+Supuestos!$B$41)
A11: 100000 | B11: =Supuestos!$B$65 | C11: =B11/(1-Supuestos!$B$40) | D11: 24 | E11: =A11*D11 | F11: =E11-A11*B11 | G11: =IF(D11=0,0,(D11-B11)/D11) | H11: =E11*(1+Supuestos!$B$41)
A12: 200000 | B12: =Supuestos!$B$65 | C12: =B12/(1-Supuestos!$B$40) | D12: 16 | E12: =A12*D12 | F12: =E12-A12*B12 | G12: =IF(D12=0,0,(D12-B12)/D12) | H12: =E12*(1+Supuestos!$B$41)
A13: 500000 | B13: =Supuestos!$B$65 | C13: =B13/(1-Supuestos!$B$40) | D13: 10 | E13: =A13*D13 | F13: =E13-A13*B13 | G13: =IF(D13=0,0,(D13-B13)/D13) | H13: =E13*(1+Supuestos!$B$41)
A14: 1000000 | B14: =Supuestos!$B$65 | C14: =B14/(1-Supuestos!$B$40) | D14: 8 | E14: =A14*D14 | F14: =E14-A14*B14 | G14: =IF(D14=0,0,(D14-B14)/D14) | H14: =E14*(1+Supuestos!$B$41)

Sheet SMS
A1: SMS — SMS (AWS End User Messaging)
A2: Solo COSTO DE ENVÍO (variable), SIN costos fijos (ver hoja 'Resumen'). Margen = Ingreso − costo de envío = margen de contribución. Si 'Precio lista' ≥ 'Precio mín.', llegás al margen objetivo. 'Precio lista' (azul) es editable por tramo.
A4: Volumen mensual (SMS) | B4: Costo de envío unit. (COP) | C4: Precio mín. ≥margen (COP) | D4: Precio lista (COP) | E4: Ingreso (COP) | F4: Margen (COP) | G4: % Margen | H4: Total + IVA (COP)
A5: 1000 | B5: =Supuestos!$B$66 | C5: =B5/(1-Supuestos!$B$40) | D5: 55 | E5: =A5*D5 | F5: =E5-A5*B5 | G5: =IF(D5=0,0,(D5-B5)/D5) | H5: =E5*(1+Supuestos!$B$41)
A6: 2000 | B6: =Supuestos!$B$66 | C6: =B6/(1-Supuestos!$B$40) | D6: 50 | E6: =A6*D6 | F6: =E6-A6*B6 | G6: =IF(D6=0,0,(D6-B6)/D6) | H6: =E6*(1+Supuestos!$B$41)
A7: 5000 | B7: =Supuestos!$B$66 | C7: =B7/(1-Supuestos!$B$40) | D7: 45 | E7: =A7*D7 | F7: =E7-A7*B7 | G7: =IF(D7=0,0,(D7-B7)/D7) | H7: =E7*(1+Supuestos!$B$41)
A8: 10000 | B8: =Supuestos!$B$66 | C8: =B8/(1-Supuestos!$B$40) | D8: 40 | E8: =A8*D8 | F8: =E8-A8*B8 | G8: =IF(D8=0,0,(D8-B8)/D8) | H8: =E8*(1+Supuestos!$B$41)
A9: 20000 | B9: =Supuestos!$B$66 | C9: =B9/(1-Supuestos!$B$40) | D9: 35 | E9: =A9*D9 | F9: =E9-A9*B9 | G9: =IF(D9=0,0,(D9-B9)/D9) | H9: =E9*(1+Supuestos!$B$41)
A10: 50000 | B10: =Supuestos!$B$66 | C10: =B10/(1-Supuestos!$B$40) | D10: 28 | E10: =A10*D10 | F10: =E10-A10*B10 | G10: =IF(D10=0,0,(D10-B10)/D10) | H10: =E10*(1+Supuestos!$B$41)
A11: 100000 | B11: =Supuestos!$B$66 | C11: =B11/(1-Supuestos!$B$40) | D11: 22 | E11: =A11*D11 | F11: =E11-A11*B11 | G11: =IF(D11=0,0,(D11-B11)/D11) | H11: =E11*(1+Supuestos!$B$41)
A12: 200000 | B12: =Supuestos!$B$66 | C12: =B12/(1-Supuestos!$B$40) | D12: 18 | E12: =A12*D12 | F12: =E12-A12*B12 | G12: =IF(D12=0,0,(D12-B12)/D12) | H12: =E12*(1+Supuestos!$B$41)
A13: 500000 | B13: =Supuestos!$B$66 | C13: =B13/(1-Supuestos!$B$40) | D13: 14 | E13: =A13*D13 | F13: =E13-A13*B13 | G13: =IF(D13=0,0,(D13-B13)/D13) | H13: =E13*(1+Supuestos!$B$41)
A14: 1000000 | B14: =Supuestos!$B$66 | C14: =B14/(1-Supuestos!$B$40) | D14: 10 | E14: =A14*D14 | F14: =E14-A14*B14 | G14: =IF(D14=0,0,(D14-B14)/D14) | H14: =E14*(1+Supuestos!$B$41)

Sheet WhatsApp
A1: WhatsApp — WhatsApp (plantilla marketing, Meta)
A2: Solo COSTO DE ENVÍO (variable), SIN costos fijos (ver hoja 'Resumen'). Margen = Ingreso − costo de envío = margen de contribución. Si 'Precio lista' ≥ 'Precio mín.', llegás al margen objetivo. 'Precio lista' (azul) es editable por tramo.
A4: Volumen mensual (mensajes) | B4: Costo de envío unit. (COP) | C4: Precio mín. ≥margen (COP) | D4: Precio lista (COP) | E4: Ingreso (COP) | F4: Margen (COP) | G4: % Margen | H4: Total + IVA (COP)
A5: 1000 | B5: =Supuestos!$B$67 | C5: =B5/(1-Supuestos!$B$40) | D5: 130 | E5: =A5*D5 | F5: =E5-A5*B5 | G5: =IF(D5=0,0,(D5-B5)/D5) | H5: =E5*(1+Supuestos!$B$41)
A6: 2000 | B6: =Supuestos!$B$67 | C6: =B6/(1-Supuestos!$B$40) | D6: 125 | E6: =A6*D6 | F6: =E6-A6*B6 | G6: =IF(D6=0,0,(D6-B6)/D6) | H6: =E6*(1+Supuestos!$B$41)
A7: 5000 | B7: =Supuestos!$B$67 | C7: =B7/(1-Supuestos!$B$40) | D7: 118 | E7: =A7*D7 | F7: =E7-A7*B7 | G7: =IF(D7=0,0,(D7-B7)/D7) | H7: =E7*(1+Supuestos!$B$41)
A8: 10000 | B8: =Supuestos!$B$67 | C8: =B8/(1-Supuestos!$B$40) | D8: 110 | E8: =A8*D8 | F8: =E8-A8*B8 | G8: =IF(D8=0,0,(D8-B8)/D8) | H8: =E8*(1+Supuestos!$B$41)
A9: 20000 | B9: =Supuestos!$B$67 | C9: =B9/(1-Supuestos!$B$40) | D9: 100 | E9: =A9*D9 | F9: =E9-A9*B9 | G9: =IF(D9=0,0,(D9-B9)/D9) | H9: =E9*(1+Supuestos!$B$41)
A10: 50000 | B10: =Supuestos!$B$67 | C10: =B10/(1-Supuestos!$B$40) | D10: 90 | E10: =A10*D10 | F10: =E10-A10*B10 | G10: =IF(D10=0,0,(D10-B10)/D10) | H10: =E10*(1+Supuestos!$B$41)
A11: 100000 | B11: =Supuestos!$B$67 | C11: =B11/(1-Supuestos!$B$40) | D11: 82 | E11: =A11*D11 | F11: =E11-A11*B11 | G11: =IF(D11=0,0,(D11-B11)/D11) | H11: =E11*(1+Supuestos!$B$41)
A12: 200000 | B12: =Supuestos!$B$67 | C12: =B12/(1-Supuestos!$B$40) | D12: 76 | E12: =A12*D12 | F12: =E12-A12*B12 | G12: =IF(D12=0,0,(D12-B12)/D12) | H12: =E12*(1+Supuestos!$B$41)
A13: 500000 | B13: =Supuestos!$B$67 | C13: =B13/(1-Supuestos!$B$40) | D13: 70 | E13: =A13*D13 | F13: =E13-A13*B13 | G13: =IF(D13=0,0,(D13-B13)/D13) | H13: =E13*(1+Supuestos!$B$41)
A14: 1000000 | B14: =Supuestos!$B$67 | C14: =B14/(1-Supuestos!$B$40) | D14: 65 | E14: =A14*D14 | F14: =E14-A14*B14 | G14: =IF(D14=0,0,(D14-B14)/D14) | H14: =E14*(1+Supuestos!$B$41)

Sheet Voz
A1: Voz — Voz — TTS (por minuto)
A2: Solo COSTO DE ENVÍO (variable), SIN costos fijos (ver hoja 'Resumen'). Margen = Ingreso − costo de envío = margen de contribución. Si 'Precio lista' ≥ 'Precio mín.', llegás al margen objetivo. 'Precio lista' (azul) es editable por tramo.
A4: Volumen mensual (minutos) | B4: Costo de envío unit. (COP) | C4: Precio mín. ≥margen (COP) | D4: Precio lista (COP) | E4: Ingreso (COP) | F4: Margen (COP) | G4: % Margen | H4: Total + IVA (COP)
A5: 1000 | B5: =Supuestos!$B$68 | C5: =B5/(1-Supuestos!$B$40) | D5: 150 | E5: =A5*D5 | F5: =E5-A5*B5 | G5: =IF(D5=0,0,(D5-B5)/D5) | H5: =E5*(1+Supuestos!$B$41)
A6: 2000 | B6: =Supuestos!$B$68 | C6: =B6/(1-Supuestos!$B$40) | D6: 140 | E6: =A6*D6 | F6: =E6-A6*B6 | G6: =IF(D6=0,0,(D6-B6)/D6) | H6: =E6*(1+Supuestos!$B$41)
A7: 5000 | B7: =Supuestos!$B$68 | C7: =B7/(1-Supuestos!$B$40) | D7: 130 | E7: =A7*D7 | F7: =E7-A7*B7 | G7: =IF(D7=0,0,(D7-B7)/D7) | H7: =E7*(1+Supuestos!$B$41)
A8: 10000 | B8: =Supuestos!$B$68 | C8: =B8/(1-Supuestos!$B$40) | D8: 120 | E8: =A8*D8 | F8: =E8-A8*B8 | G8: =IF(D8=0,0,(D8-B8)/D8) | H8: =E8*(1+Supuestos!$B$41)
A9: 20000 | B9: =Supuestos!$B$68 | C9: =B9/(1-Supuestos!$B$40) | D9: 110 | E9: =A9*D9 | F9: =E9-A9*B9 | G9: =IF(D9=0,0,(D9-B9)/D9) | H9: =E9*(1+Supuestos!$B$41)
A10: 50000 | B10: =Supuestos!$B$68 | C10: =B10/(1-Supuestos!$B$40) | D10: 95 | E10: =A10*D10 | F10: =E10-A10*B10 | G10: =IF(D10=0,0,(D10-B10)/D10) | H10: =E10*(1+Supuestos!$B$41)
A11: 100000 | B11: =Supuestos!$B$68 | C11: =B11/(1-Supuestos!$B$40) | D11: 80 | E11: =A11*D11 | F11: =E11-A11*B11 | G11: =IF(D11=0,0,(D11-B11)/D11) | H11: =E11*(1+Supuestos!$B$41)
A12: 200000 | B12: =Supuestos!$B$68 | C12: =B12/(1-Supuestos!$B$40) | D12: 70 | E12: =A12*D12 | F12: =E12-A12*B12 | G12: =IF(D12=0,0,(D12-B12)/D12) | H12: =E12*(1+Supuestos!$B$41)
A13: 500000 | B13: =Supuestos!$B$68 | C13: =B13/(1-Supuestos!$B$40) | D13: 60 | E13: =A13*D13 | F13: =E13-A13*B13 | G13: =IF(D13=0,0,(D13-B13)/D13) | H13: =E13*(1+Supuestos!$B$41)
A14: 1000000 | B14: =Supuestos!$B$68 | C14: =B14/(1-Supuestos!$B$40) | D14: 48 | E14: =A14*D14 | F14: =E14-A14*B14 | G14: =IF(D14=0,0,(D14-B14)/D14) | H14: =E14*(1+Supuestos!$B$41)

Sheet Cotizador
A1: Cotizador rápido
A2: Editá las celdas azules. Muestra el COSTO DE ENVÍO y el margen (sin fijos).
A4: ENTRADAS
A5: Canal | B5: EM | C5: EM/EAU/EAP/SMS/WhatsApp/Voz
A6: Cantidad de envíos | B6: 50000 | C6: correos/SMS/mensajes/minutos
A7: MB de adjunto (EAU/EAP) | B7: 2
A8: Segmentos por SMS | B8: 1
A9: Precio unit. a cobrar (COP) | B9: 6 | C9: tu precio; comparalo con el mínimo de abajo
A10: ¿Recarga por Wompi? | B10: Sí | C10: Sí/No
A12: RESULTADO
A13: Costo de envío unit. (USD) | B13: =IF(B5="EM",Supuestos!$B$53,IF(B5="EAU",Supuestos!$B$53+B7*Supuestos!$B$11,IF(B5="EAP",Supuestos!$B$53+B7*Supuestos!$B$11,IF(B5="SMS",Supuestos!$B$54+B8*Supuestos!$B$22,IF(B5="WhatsApp",Supuestos!$B$54+Supuestos!$B$23,IF(B5="Voz",Supuestos!$B$54+Supuestos!$B$24,0))))))
A14: Costo de envío unit. (COP) | B14: =B13*Supuestos!$B$7
A15: Costo total de envío (COP) | B15: =B6*B14
A16: Precio unit. mínimo (≥ margen) (COP) | B16: =B14/(1-Supuestos!$B$40) | C16: por debajo no llegás al margen objetivo
A17: Ingreso (sin IVA) (COP) | B17: =B6*B9
A18: Margen de contribución (COP) | B18: =B17-B15 | C18: ingreso − costo de envío
A19: % Margen | B19: =IF(B17=0,0,B18/B17)
A20: Total a cobrar (con IVA) (COP) | B20: =B17*(1+Supuestos!$B$41)
A21: Comisión Wompi (si aplica) (COP) | B21: =IF(B10="Sí",B20*Supuestos!$B$42+Supuestos!$B$43,0)
A22: Margen tras comisión Wompi (COP) | B22: =B18-B21

Sheet Adjunto URL vs archivo
A1: ¿Adjuntar el archivo o mandarlo como enlace (URL)?
A2: Adjuntar (modo ONFILE): SES cobra US$0.12/GB a CADA destinatario. Enlace (modo ONLINE): S3 cobra US$0.09/GB SOLO a quien descarga, y el archivo se guarda una vez. → El enlace casi siempre es MÁS BARATO.
A4: MB del archivo | B4: 2
A5: Destinatarios | B5: 100000
A7: % que descarga | B7: Costo ADJUNTO (SES) (COP) | C7: Costo URL (S3) (COP) | D7: Ahorro con URL (COP) | E7: Ahorro %
A8: 0.2 | B8: =$B$5*$B$4*Supuestos!$B$11*Supuestos!$B$7 | C8: =$B$5*A8*$B$4*(Supuestos!$B$17/1024)*Supuestos!$B$7 | D8: =B8-C8 | E8: =IF(B8=0,0,(B8-C8)/B8)
A9: 0.5 | B9: =$B$5*$B$4*Supuestos!$B$11*Supuestos!$B$7 | C9: =$B$5*A9*$B$4*(Supuestos!$B$17/1024)*Supuestos!$B$7 | D9: =B9-C9 | E9: =IF(B9=0,0,(B9-C9)/B9)
A10: 1 | B10: =$B$5*$B$4*Supuestos!$B$11*Supuestos!$B$7 | C10: =$B$5*A10*$B$4*(Supuestos!$B$17/1024)*Supuestos!$B$7 | D10: =B10-C10 | E10: =IF(B10=0,0,(B10-C10)/B10)
A12: Además del costo: el enlace mejora la ENTREGABILIDAD (los adjuntos grandes caen en spam) y evita el límite de tamaño de correo. En contra: el archivo público en S3 no sirve para documentos sensibles (ahí usá adjunto o enlace firmado que expira).

Sheet Resumen
A1: Resumen: costos fijos y punto de equilibrio
A2: Los fijos NO están en las tablas de canal. Son muy bajos y se cubren con poco volumen: el 'punto de equilibrio' es cuántos envíos/mes de ese canal (a la tarifa plana) alcanzan para pagarlos.
A4: Total fijos mensuales (COP) | B4: =Supuestos!$B$50
A6: Canal | B6: Costo de envío (COP) | C6: Tarifa plana actual (COP) | D6: % Margen a tarifa plana | E6: Envíos/mes para cubrir fijos
A7: EM | B7: =Supuestos!$B$63 | C7: 8 | D7: =IF(C7=0,0,(C7-B7)/C7) | E7: =IF(C7<=B7,"n/a (precio<costo)",$B$4/(C7-B7))
A8: EAU | B8: =Supuestos!$B$64 | C8: 15 | D8: =IF(C8=0,0,(C8-B8)/C8) | E8: =IF(C8<=B8,"n/a (precio<costo)",$B$4/(C8-B8))
A9: EAP | B9: =Supuestos!$B$65 | C9: 40 | D9: =IF(C9=0,0,(C9-B9)/C9) | E9: =IF(C9<=B9,"n/a (precio<costo)",$B$4/(C9-B9))
A10: SMS | B10: =Supuestos!$B$66 | C10: 60 | D10: =IF(C10=0,0,(C10-B10)/C10) | E10: =IF(C10<=B10,"n/a (precio<costo)",$B$4/(C10-B10))
A11: WhatsApp | B11: =Supuestos!$B$67 | C11: 90 | D11: =IF(C11=0,0,(C11-B11)/C11) | E11: =IF(C11<=B11,"n/a (precio<costo)",$B$4/(C11-B11))
A12: Voz | B12: =Supuestos!$B$68 | C12: 120 | D12: =IF(C12=0,0,(C12-B12)/C12) | E12: =IF(C12<=B12,"n/a (precio<costo)",$B$4/(C12-B12))
